2022-03-02 20:12:23,936 ERROR: Exception on /login [POST] [in /Users/jakebeard/opt/miniconda3/lib/python3.8/site-packages/flask/app.py:1440]
Traceback (most recent call last):
  File "/Users/jakebeard/opt/miniconda3/lib/python3.8/site-packages/sqlalchemy/engine/base.py", line 1276, in _execute_context
    self.dialect.do_execute(
  File "/Users/jakebeard/opt/miniconda3/lib/python3.8/site-packages/sqlalchemy/engine/default.py", line 608, in do_execute
    cursor.execute(statement, parameters)
sqlite3.OperationalError: no such table: user

The above exception was the direct cause of the following exception:

Traceback (most recent call last):
  File "/Users/jakebeard/opt/miniconda3/lib/python3.8/site-packages/flask/app.py", line 2051, in wsgi_app
    response = self.full_dispatch_request()
  File "/Users/jakebeard/opt/miniconda3/lib/python3.8/site-packages/flask/app.py", line 1501, in full_dispatch_request
    rv = self.handle_user_exception(e)
  File "/Users/jakebeard/opt/miniconda3/lib/python3.8/site-packages/flask/app.py", line 1499, in full_dispatch_request
    rv = self.dispatch_request()
  File "/Users/jakebeard/opt/miniconda3/lib/python3.8/site-packages/flask/app.py", line 1485, in dispatch_request
    return self.ensure_sync(self.view_functions[rule.endpoint])(**req.view_args)
  File "/Users/jakebeard/Documents/GitHub/microblog/app/routes.py", line 61, in login
    user = User.query.filter_by(username=form.username.data).first()
  File "/Users/jakebeard/opt/miniconda3/lib/python3.8/site-packages/sqlalchemy/orm/query.py", line 3429, in first
    ret = list(self[0:1])
  File "/Users/jakebeard/opt/miniconda3/lib/python3.8/site-packages/sqlalchemy/orm/query.py", line 3203, in __getitem__
    return list(res)
  File "/Users/jakebeard/opt/miniconda3/lib/python3.8/site-packages/sqlalchemy/orm/query.py", line 3535, in __iter__
    return self._execute_and_instances(context)
  File "/Users/jakebeard/opt/miniconda3/lib/python3.8/site-packages/sqlalchemy/orm/query.py", line 3560, in _execute_and_instances
    result = conn.execute(querycontext.statement, self._params)
  File "/Users/jakebeard/opt/miniconda3/lib/python3.8/site-packages/sqlalchemy/engine/base.py", line 1011, in execute
    return meth(self, multiparams, params)
  File "/Users/jakebeard/opt/miniconda3/lib/python3.8/site-packages/sqlalchemy/sql/elements.py", line 298, in _execute_on_connection
    return connection._execute_clauseelement(self, multiparams, params)
  File "/Users/jakebeard/opt/miniconda3/lib/python3.8/site-packages/sqlalchemy/engine/base.py", line 1124, in _execute_clauseelement
    ret = self._execute_context(
  File "/Users/jakebeard/opt/miniconda3/lib/python3.8/site-packages/sqlalchemy/engine/base.py", line 1316, in _execute_context
    self._handle_dbapi_exception(
  File "/Users/jakebeard/opt/miniconda3/lib/python3.8/site-packages/sqlalchemy/engine/base.py", line 1510, in _handle_dbapi_exception
    util.raise_(
  File "/Users/jakebeard/opt/miniconda3/lib/python3.8/site-packages/sqlalchemy/util/compat.py", line 182, in raise_
    raise exception
  File "/Users/jakebeard/opt/miniconda3/lib/python3.8/site-packages/sqlalchemy/engine/base.py", line 1276, in _execute_context
    self.dialect.do_execute(
  File "/Users/jakebeard/opt/miniconda3/lib/python3.8/site-packages/sqlalchemy/engine/default.py", line 608, in do_execute
    cursor.execute(statement, parameters)
sqlalchemy.exc.OperationalError: (sqlite3.OperationalError) no such table: user
[SQL: SELECT user.id AS user_id, user.username AS user_username, user.email AS user_email, user.password_hash AS user_password_hash, user.about_me AS user_about_me, user.last_seen AS user_last_seen 
FROM user 
WHERE user.username = ?
 LIMIT ? OFFSET ?]
[parameters: ('jakee', 1, 0)]
(Background on this error at: http://sqlalche.me/e/13/e3q8)
2022-03-02 20:14:08,902 ERROR: Exception on /register [POST] [in /Users/jakebeard/opt/miniconda3/lib/python3.8/site-packages/flask/app.py:1440]
Traceback (most recent call last):
  File "/Users/jakebeard/opt/miniconda3/lib/python3.8/site-packages/sqlalchemy/engine/base.py", line 1276, in _execute_context
    self.dialect.do_execute(
  File "/Users/jakebeard/opt/miniconda3/lib/python3.8/site-packages/sqlalchemy/engine/default.py", line 608, in do_execute
    cursor.execute(statement, parameters)
sqlite3.OperationalError: no such table: user

The above exception was the direct cause of the following exception:

Traceback (most recent call last):
  File "/Users/jakebeard/opt/miniconda3/lib/python3.8/site-packages/flask/app.py", line 2051, in wsgi_app
    response = self.full_dispatch_request()
  File "/Users/jakebeard/opt/miniconda3/lib/python3.8/site-packages/flask/app.py", line 1501, in full_dispatch_request
    rv = self.handle_user_exception(e)
  File "/Users/jakebeard/opt/miniconda3/lib/python3.8/site-packages/flask/app.py", line 1499, in full_dispatch_request
    rv = self.dispatch_request()
  File "/Users/jakebeard/opt/miniconda3/lib/python3.8/site-packages/flask/app.py", line 1485, in dispatch_request
    return self.ensure_sync(self.view_functions[rule.endpoint])(**req.view_args)
  File "/Users/jakebeard/Documents/GitHub/microblog/app/routes.py", line 84, in register
    if form.validate_on_submit():
  File "/Users/jakebeard/opt/miniconda3/lib/python3.8/site-packages/flask_wtf/form.py", line 86, in validate_on_submit
    return self.is_submitted() and self.validate()
  File "/Users/jakebeard/opt/miniconda3/lib/python3.8/site-packages/wtforms/form.py", line 329, in validate
    return super().validate(extra)
  File "/Users/jakebeard/opt/miniconda3/lib/python3.8/site-packages/wtforms/form.py", line 146, in validate
    if not field.validate(self, extra):
  File "/Users/jakebeard/opt/miniconda3/lib/python3.8/site-packages/wtforms/fields/core.py", line 242, in validate
    stop_validation = self._run_validation_chain(form, chain)
  File "/Users/jakebeard/opt/miniconda3/lib/python3.8/site-packages/wtforms/fields/core.py", line 262, in _run_validation_chain
    validator(form, self)
  File "/Users/jakebeard/Documents/GitHub/microblog/app/forms.py", line 25, in validate_username
    user = User.query.filter_by(username=username.data).first()
  File "/Users/jakebeard/opt/miniconda3/lib/python3.8/site-packages/sqlalchemy/orm/query.py", line 3429, in first
    ret = list(self[0:1])
  File "/Users/jakebeard/opt/miniconda3/lib/python3.8/site-packages/sqlalchemy/orm/query.py", line 3203, in __getitem__
    return list(res)
  File "/Users/jakebeard/opt/miniconda3/lib/python3.8/site-packages/sqlalchemy/orm/query.py", line 3535, in __iter__
    return self._execute_and_instances(context)
  File "/Users/jakebeard/opt/miniconda3/lib/python3.8/site-packages/sqlalchemy/orm/query.py", line 3560, in _execute_and_instances
    result = conn.execute(querycontext.statement, self._params)
  File "/Users/jakebeard/opt/miniconda3/lib/python3.8/site-packages/sqlalchemy/engine/base.py", line 1011, in execute
    return meth(self, multiparams, params)
  File "/Users/jakebeard/opt/miniconda3/lib/python3.8/site-packages/sqlalchemy/sql/elements.py", line 298, in _execute_on_connection
    return connection._execute_clauseelement(self, multiparams, params)
  File "/Users/jakebeard/opt/miniconda3/lib/python3.8/site-packages/sqlalchemy/engine/base.py", line 1124, in _execute_clauseelement
    ret = self._execute_context(
  File "/Users/jakebeard/opt/miniconda3/lib/python3.8/site-packages/sqlalchemy/engine/base.py", line 1316, in _execute_context
    self._handle_dbapi_exception(
  File "/Users/jakebeard/opt/miniconda3/lib/python3.8/site-packages/sqlalchemy/engine/base.py", line 1510, in _handle_dbapi_exception
    util.raise_(
  File "/Users/jakebeard/opt/miniconda3/lib/python3.8/site-packages/sqlalchemy/util/compat.py", line 182, in raise_
    raise exception
  File "/Users/jakebeard/opt/miniconda3/lib/python3.8/site-packages/sqlalchemy/engine/base.py", line 1276, in _execute_context
    self.dialect.do_execute(
  File "/Users/jakebeard/opt/miniconda3/lib/python3.8/site-packages/sqlalchemy/engine/default.py", line 608, in do_execute
    cursor.execute(statement, parameters)
sqlalchemy.exc.OperationalError: (sqlite3.OperationalError) no such table: user
[SQL: SELECT user.id AS user_id, user.username AS user_username, user.email AS user_email, user.password_hash AS user_password_hash, user.about_me AS user_about_me, user.last_seen AS user_last_seen 
FROM user 
WHERE user.username = ?
 LIMIT ? OFFSET ?]
[parameters: ('jake', 1, 0)]
(Background on this error at: http://sqlalche.me/e/13/e3q8)
